Workbook

Sheet 2020
A1: Fossil ammonia | D1: Cost | E1: Low | F1: High | N1: Prices
A2: ammonia | B2: 1 | C2: kilogram | D2: =SUM(D3:D12) -> 0.27850023 | E2: =SUM(E3:E12) -> 0.23990012 | F2: =SUM(F3:F12) -> 0.31710035 | N2: Category | O2: Price | P2: Low | Q2: High
A3: natural gas, feedstock | B3: 0.62178 | C3: cubic meter | D3: =$B3*O3 -> 0.044684711 | E3: =$B3*P3 -> 0.022342355 | F3: =$B3*Q3 -> 0.067027066 | N3: natural gas, feedstock | O3: 0.07186579 | P3: =O3*0.5 -> 0.035932895 | Q3: =O3*1.5 -> 0.10779868 | R3: USD per m3
A4: natural gas, heating | B4: 13.952 | C4: megajoule | D4: =$B4*O4 -> 0.027395396 | E4: =$B4*P4 -> 0.013697698 | F4: =$B4*Q4 -> 0.041093094 | N4: natural gas, heating | O4: =1.96354616244411/1000 -> 0.0019635462 | P4: =O4*0.5 -> 0.00098177308 | Q4: =O4*1.5 -> 0.0029453192 | R4: USD per MJ | T4: =O4*1000 -> 1.9635462 | U4: =P4*1000 -> 0.98177308 | V4: =Q4*1000 -> 2.9453192
A5: electricity, from grid | B5: 0.049232 | C5: kilowatt hour | D5: =$B5*O5 -> 0.005120128 | E5: =$B5*P5 -> 0.002560064 | F5: =$B5*Q5 -> 0.007680192 | N5: electricity, from grid | O5: 0.104 | P5: =O5*0.5 -> 0.052 | Q5: =O5*1.5 -> 0.156 | R5: USD per kWh
A6: solar hydrogen, 25 bar | B6: 0 | C6: kilogram | D6: =$B6*O6 -> 0 | E6: =$B6*P6 -> 0 | F6: =$B6*Q6 -> 0 | N6: solar hydrogen, 25 bar | O6: 9.22 | P6: 8.34 | Q6: 15.9 | R6: USD per kg
A7: wind hydrogen, 25 bar | B7: 0 | C7: kilogram | D7: =$B7*O7 -> 0 | E7: =$B7*P7 -> 0 | F7: =$B7*Q7 -> 0 | N7: wind hydrogen, 25 bar | O7: 6.88 | P7: 5.23 | Q7: 8.48 | R7: USD per kg
A8: nitrogen gaseous | B8: 0 | C8: kilogram | D8: =$B8*O8 -> 0 | E8: =$B8*P8 -> 0 | F8: =$B8*Q8 -> 0 | N8: nitrogen gaseous | O8: =91/1000*596.2/607.5 -> 0.089307325 | P8: =O8*0.5 -> 0.044653663 | Q8: =O8*1.5 -> 0.13396099 | R8: USD per kg
A9: CO2 emissions, fossil | B9: 1.4326 | C9: kilogram | D9: =$B9*O9 -> 0 | E9: =$B9*P9 -> 0 | F9: =$B9*Q9 -> 0 | N9: CO2 emissions, fossil | O9: 0 | P9: 0 | Q9: 0 | R9: USD per kg
A10: CO2 emissions, biogenic | B10: 0 | C10: kilogram | D10: =$B10*O10 -> 0 | E10: =$B10*P10 -> 0 | F10: =$B10*Q10 -> 0 | N10: CO2 emissions, biogenic | O10: 0 | P10: 0 | Q10: 0 | R10: USD per kg
A11: CAPEX contribution | B11: - | C11: - | D11: =O13 -> 0.1331 | E11: =D11 -> 0.1331 | F11: =E11 -> 0.1331
A12: Fixed costs contribution | B12: - | C12: - | D12: =O14 -> 0.0682 | E12: =D12 -> 0.0682 | F12: =E12 -> 0.0682 | N12: For fossil routes
N13: CAPEX contribution | O13: 0.1331 | P13: 0 | Q13: 0 | R13: USD2019 kg-1 ammonia
A14: Blue ammonia | D14: Cost | E14: Low | F14: High | N14: Fixed costs contribution | O14: 0.0682 | P14: 0 | Q14: 0 | R14: USD2019 kg-1 ammonia
A15: ammonia | B15: 1 | C15: kilogram | D15: =SUM(D16:D25) -> 0.29807757 | E15: =SUM(E16:E25) -> 0.24968879 | F15: =SUM(F16:F25) -> 0.34646636
A16: natural gas, feedstock | B16: 0.62178 | C16: cubic meter | D16: =$B16*O3 -> 0.044684711 | E16: =$B16*P3 -> 0.022342355 | F16: =$B16*Q3 -> 0.067027066 | N16: For green routes
A17: natural gas, heating | B17: 13.952 | C17: cubic meter | D17: =$B17*O4 -> 0.027395396 | E17: =$B17*P4 -> 0.013697698 | F17: =$B17*Q4 -> 0.041093094 | N17: CAPEX contribution | O17: 0.0799 | P17: 0 | Q17: 0 | R17: USD2019 kg-1 ammonia
A18: electricity, from grid | B18: 0.23747564 | C18: kilowatt hour | D18: =$B18*O5 -> 0.024697467 | E18: =$B18*P5 -> 0.012348733 | F18: =$B18*Q5 -> 0.0370462 | N18: Fixed costs contribution | O18: 0.0491 | P18: 0 | Q18: 0 | R18: USD2019 kg-1 ammonia
A19: solar hydrogen, 25 bar | B19: 0 | C19: kilogram | D19: =$B19*O6 -> 0 | E19: =$B19*P6 -> 0 | F19: =$B19*Q6 -> 0
A20: wind hydrogen, 25 bar | B20: 0 | C20: kilogram | D20: =$B20*O7 -> 0 | E20: =$B20*P7 -> 0 | F20: =$B20*Q7 -> 0
A21: nitrogen gaseous | B21: 0 | C21: kilogram | D21: =$B21*O8 -> 0 | E21: =$B21*P8 -> 0 | F21: =$B21*Q8 -> 0
A22: CO2 emissions, fossil | B22: 0.14326 | C22: kilogram | D22: =$B22*O9 -> 0 | E22: =$B22*P9 -> 0 | F22: =$B22*Q9 -> 0
A23: CO2 emissions, biogenic | B23: 0 | C23: kilogram | D23: =$B23*O10 -> 0 | E23: =$B23*P10 -> 0 | F23: =$B23*Q10 -> 0
A24: CAPEX contribution | B24: - | C24: - | D24: =O13 -> 0.1331 | E24: =D24 -> 0.1331 | F24: =E24 -> 0.1331
A25: Fixed costs contribution | B25: - | C25: - | D25: =O14 -> 0.0682 | E25: =D25 -> 0.0682 | F25: =E25 -> 0.0682
A27: Solar ammonia | D27: Cost | E27: Low | F27: High
A28: ammonia | B28: 1 | C28: kilogram | D28: =SUM(D29:D38) -> 1.8823295 | E28: =SUM(E29:E38) -> 1.6621447 | F28: =SUM(F29:F38) -> 3.1233142
A29: natural gas, feedstock | B29: 0 | C29: cubic meter | D29: =$B29*O3 -> 0 | E29: =$B29*P3 -> 0 | F29: =$B29*Q3 -> 0
A30: natural gas, heating | B30: 0 | C30: megajoule | D30: =$B30*O4 -> 0 | E30: =$B30*P4 -> 0 | F30: =$B30*Q4 -> 0
A31: electricity, from grid | B31: 0.556 | C31: kilowatt hour | D31: =$B31*O5 -> 0.057824 | E31: =$B31*P5 -> 0.028912 | F31: =$B31*Q5 -> 0.086736
A32: solar hydrogen, 25 bar | B32: 0.176 | C32: kilogram | D32: =$B32*O6 -> 1.62272 | E32: =$B32*P6 -> 1.46784 | F32: =$B32*Q6 -> 2.7984
A33: wind hydrogen, 25 bar | B33: 0 | C33: kilogram | D33: =$B33*O7 -> 0 | E33: =$B33*P7 -> 0 | F33: =$B33*Q7 -> 0
A34: nitrogen gaseous | B34: 0.815 | C34: kilogram | D34: =$B34*O8 -> 0.07278547 | E34: =$B34*P8 -> 0.036392735 | F34: =$B34*Q8 -> 0.1091782
A35: CO2 emissions, fossil | B35: 0 | C35: kilogram | D35: =$B35*O9 -> 0 | E35: =$B35*P9 -> 0 | F35: =$B35*Q9 -> 0
A36: CO2 emissions, biogenic | B36: 0 | C36: kilogram | D36: =$B36*O10 -> 0 | E36: =$B36*P10 -> 0 | F36: =$B36*Q10 -> 0
A37: CAPEX contribution | B37: - | C37: - | D37: =O17 -> 0.0799 | E37: =D37 -> 0.0799 | F37: =E37 -> 0.0799
A38: Fixed costs contribution | B38: - | C38: - | D38: =O18 -> 0.0491 | E38: =D38 -> 0.0491 | F38: =E38 -> 0.0491
A40: Wind ammonia | D40: Cost | E40: Low | F40: High
A41: ammonia | B41: 1 | C41: kilogram | D41: =SUM(D42:D51) -> 1.4704895 | E41: =SUM(E42:E51) -> 1.1147847 | F41: =SUM(F42:F51) -> 1.8173942
A42: natural gas, feedstock | B42: 0 | C42: cubic meter | D42: =$B42*O3 -> 0 | E42: =$B42*P3 -> 0 | F42: =$B42*Q3 -> 0
...

Sheet 2030
A1: Fossil ammonia | D1: Cost | E1: Low | F1: High | N1: Prices
A2: ammonia | B2: 1 | C2: kilogram | D2: =SUM(D3:D12) -> 0.33926633 | E2: =SUM(E3:E12) -> 0.2785793 | F2: =SUM(F3:F12) -> 0.39995336 | N2: Category | O2: Price | P2: Low | Q2: High
A3: natural gas, feedstock | B3: 0.62178 | C3: cubic meter | D3: =$B3*O3 -> 0.072099968 | E3: =$B3*P3 -> 0.036049984 | F3: =$B3*Q3 -> 0.10814995 | N3: natural gas, feedstock | O3: 0.11595736 | P3: =O3*0.5 -> 0.05797868 | Q3: =O3*1.5 -> 0.17393604 | R3: USD per m3
A4: natural gas, heating | B4: 13.952 | C4: megajoule | D4: =$B4*O4 -> 0.044203199 | E4: =$B4*P4 -> 0.0221016 | F4: =$B4*Q4 -> 0.066304799 | N4: natural gas, heating | O4: =3.16823390461997/1000 -> 0.0031682339 | P4: =O4*0.5 -> 0.001584117 | Q4: =O4*1.5 -> 0.0047523509 | R4: USD per MJ | T4: =O4*1000 -> 3.1682339 | U4: =P4*1000 -> 1.584117 | V4: =Q4*1000 -> 4.7523509
A5: electricity, from grid | B5: 0.049232 | C5: kilowatt hour | D5: =$B5*O5 -> 0.005070896 | E5: =$B5*P5 -> 0.002535448 | F5: =$B5*Q5 -> 0.007606344 | N5: electricity, from grid | O5: 0.103 | P5: =O5*0.5 -> 0.0515 | Q5: =O5*1.5 -> 0.1545 | R5: USD per kWh
A6: solar hydrogen, 25 bar | B6: 0 | C6: kilogram | D6: =$B6*O6 -> 0 | E6: =$B6*P6 -> 0 | F6: =$B6*Q6 -> 0 | N6: solar hydrogen, 25 bar | O6: 6.67 | P6: 4.06 | Q6: 9.28 | R6: USD per kg
A7: wind hydrogen, 25 bar | B7: 0 | C7: kilogram | D7: =$B7*O7 -> 0 | E7: =$B7*P7 -> 0 | F7: =$B7*Q7 -> 0 | N7: wind hydrogen, 25 bar | O7: 5.75 | P7: 3.5 | Q7: 8 | R7: USD per kg
A8: nitrogen gaseous | B8: 0 | C8: kilogram | D8: =$B8*O8 -> 0 | E8: =$B8*P8 -> 0 | F8: =$B8*Q8 -> 0 | N8: nitrogen gaseous | O8: =91/1000*596.2/607.5*596.2/550.8 -> 0.096668532 | P8: =O8*0.5 -> 0.048334266 | Q8: =O8*1.5 -> 0.1450028 | R8: USD per kg
A9: CO2 emissions, fossil | B9: 1.4326 | C9: kilogram | D9: =$B9*O9 -> 0 | E9: =$B9*P9 -> 0 | F9: =$B9*Q9 -> 0 | N9: CO2 emissions, fossil | O9: 0 | P9: 0 | Q9: 0 | R9: USD per kg
A10: CO2 emissions, biogenic | B10: 0 | C10: kilogram | D10: =$B10*O10 -> 0 | E10: =$B10*P10 -> 0 | F10: =$B10*Q10 -> 0 | N10: CO2 emissions, biogenic | O10: 0 | P10: 0 | Q10: 0 | R10: USD per kg
A11: CAPEX contribution | B11: - | C11: - | D11: =O13 -> 0.14407084 | E11: =D11 -> 0.14407084 | F11: =E11 -> 0.14407084
A12: Fixed costs contribution | B12: - | C12: - | D12: =O14 -> 0.073821423 | E12: =D12 -> 0.073821423 | F12: =E12 -> 0.073821423 | N12: For fossil routes
N13: CAPEX contribution | O13: =0.1331*596.2/550.8 -> 0.14407084 | P13: 0 | Q13: 0 | R13: USD2019 kg-1 ammonia
A14: Blue ammonia | D14: Cost | E14: Low | F14: High | N14: Fixed costs contribution | O14: =0.0682*596.2/550.8 -> 0.073821423 | P14: 0 | Q14: 0 | R14: USD2019 kg-1 ammonia
A15: ammonia | B15: 1 | C15: kilogram | D15: =SUM(D16:D25) -> 0.35865542 | E15: =SUM(E16:E25) -> 0.28827384 | F15: =SUM(F16:F25) -> 0.429037
A16: natural gas, feedstock | B16: 0.62178 | C16: cubic meter | D16: =$B16*O3 -> 0.072099968 | E16: =$B16*P3 -> 0.036049984 | F16: =$B16*Q3 -> 0.10814995 | N16: For green routes
A17: natural gas, heating | B17: 13.952 | C17: cubic meter | D17: =$B17*O4 -> 0.044203199 | E17: =$B17*P4 -> 0.0221016 | F17: =$B17*Q4 -> 0.066304799 | N17: CAPEX contribution | O17: =0.0799*596.2/550.8 -> 0.086485802 | P17: 0 | Q17: 0 | R17: USD2019 kg-1 ammonia
A18: electricity, from grid | B18: 0.23747564 | C18: kilowatt hour | D18: =$B18*O5 -> 0.024459991 | E18: =$B18*P5 -> 0.012229995 | F18: =$B18*Q5 -> 0.036689986 | N18: Fixed costs contribution | O18: =0.0491*596.2/550.8 -> 0.053147095 | P18: 0 | Q18: 0 | R18: USD2019 kg-1 ammonia
A19: solar hydrogen, 25 bar | B19: 0 | C19: kilogram | D19: =$B19*O6 -> 0 | E19: =$B19*P6 -> 0 | F19: =$B19*Q6 -> 0
A20: wind hydrogen, 25 bar | B20: 0 | C20: kilogram | D20: =$B20*O7 -> 0 | E20: =$B20*P7 -> 0 | F20: =$B20*Q7 -> 0
A21: nitrogen gaseous | B21: 0 | C21: kilogram | D21: =$B21*O8 -> 0 | E21: =$B21*P8 -> 0 | F21: =$B21*Q8 -> 0
A22: CO2 emissions, fossil | B22: 0.14326 | C22: kilogram | D22: =$B22*O9 -> 0 | E22: =$B22*P9 -> 0 | F22: =$B22*Q9 -> 0
A23: CO2 emissions, biogenic | B23: 0 | C23: kilogram | D23: =$B23*O10 -> 0 | E23: =$B23*P10 -> 0 | F23: =$B23*Q10 -> 0
A24: CAPEX contribution | B24: - | C24: - | D24: =O13 -> 0.14407084 | E24: =D24 -> 0.14407084 | F24: =E24 -> 0.14407084
A25: Fixed costs contribution | B25: - | C25: - | D25: =O14 -> 0.073821423 | E25: =D25 -> 0.073821423 | F25: =E25 -> 0.073821423
A27: Solar ammonia | D27: Cost | E27: Low | F27: High
A28: ammonia | B28: 1 | C28: kilogram | D28: =SUM(D29:D38) -> 1.4496058 | E28: =SUM(E29:E38) -> 0.92221932 | F28: =SUM(F29:F38) -> 1.9769922
A29: natural gas, feedstock | B29: 0 | C29: cubic meter | D29: =$B29*O3 -> 0 | E29: =$B29*P3 -> 0 | F29: =$B29*Q3 -> 0
A30: natural gas, heating | B30: 0 | C30: megajoule | D30: =$B30*O4 -> 0 | E30: =$B30*P4 -> 0 | F30: =$B30*Q4 -> 0
A31: electricity, from grid | B31: 0.556 | C31: kilowatt hour | D31: =$B31*O5 -> 0.057268 | E31: =$B31*P5 -> 0.028634 | F31: =$B31*Q5 -> 0.085902
A32: solar hydrogen, 25 bar | B32: 0.176 | C32: kilogram | D32: =$B32*O6 -> 1.17392 | E32: =$B32*P6 -> 0.71456 | F32: =$B32*Q6 -> 1.63328
A33: wind hydrogen, 25 bar | B33: 0 | C33: kilogram | D33: =$B33*O7 -> 0 | E33: =$B33*P7 -> 0 | F33: =$B33*Q7 -> 0
A34: nitrogen gaseous | B34: 0.815 | C34: kilogram | D34: =$B34*O8 -> 0.078784853 | E34: =$B34*P8 -> 0.039392427 | F34: =$B34*Q8 -> 0.11817728
A35: CO2 emissions, fossil | B35: 0 | C35: kilogram | D35: =$B35*O9 -> 0 | E35: =$B35*P9 -> 0 | F35: =$B35*Q9 -> 0
A36: CO2 emissions, biogenic | B36: 0 | C36: kilogram | D36: =$B36*O10 -> 0 | E36: =$B36*P10 -> 0 | F36: =$B36*Q10 -> 0
A37: CAPEX contribution | B37: - | C37: - | D37: =O17 -> 0.086485802 | E37: =D37 -> 0.086485802 | F37: =E37 -> 0.086485802
A38: Fixed costs contribution | B38: - | C38: - | D38: =O18 -> 0.053147095 | E38: =D38 -> 0.053147095 | F38: =E38 -> 0.053147095
A40: Wind ammonia | D40: Cost | E40: Low | F40: High
A41: ammonia | B41: 1 | C41: kilogram | D41: =SUM(D42:D51) -> 1.2876858 | E41: =SUM(E42:E51) -> 0.82365932 | F41: =SUM(F42:F51) -> 1.7517122
A42: natural gas, feedstock | B42: 0 | C42: cubic meter | D42: =$B42*O3 -> 0 | E42: =$B42*P3 -> 0 | F42: =$B42*Q3 -> 0
...

Sheet 2040
A1: Fossil ammonia | D1: Cost | E1: Low | F1: High | N1: Prices
A2: ammonia | B2: 1 | C2: kilogram | D2: =SUM(D3:D12) -> 0.36444023 | E2: =SUM(E3:E12) -> 0.3001462 | F2: =SUM(F3:F12) -> 0.42873427 | N2: Category | O2: Price | P2: Low | Q2: High
A3: natural gas, feedstock | B3: 0.62178 | C3: cubic meter | D3: =$B3*O3 -> 0.076633199 | E3: =$B3*P3 -> 0.0383166 | F3: =$B3*Q3 -> 0.1149498 | N3: natural gas, feedstock | O3: 0.12324809 | P3: =O3*0.5 -> 0.061624047 | Q3: =O3*1.5 -> 0.18487214 | R3: USD per m3
A4: natural gas, heating | B4: 13.952 | C4: megajoule | D4: =$B4*O4 -> 0.046982443 | E4: =$B4*P4 -> 0.023491221 | F4: =$B4*Q4 -> 0.070473664 | N4: natural gas, heating | O4: =3.36743423994039/1000 -> 0.0033674342 | P4: =O4*0.5 -> 0.0016837171 | Q4: =O4*1.5 -> 0.0050511514 | R4: USD per MJ | T4: =O4*1000 -> 3.3674342 | U4: =P4*1000 -> 1.6837171 | V4: =Q4*1000 -> 5.0511514
A5: electricity, from grid | B5: 0.049232 | C5: kilowatt hour | D5: =$B5*O5 -> 0.004972432 | E5: =$B5*P5 -> 0.002486216 | F5: =$B5*Q5 -> 0.007458648 | N5: electricity, from grid | O5: 0.101 | P5: =O5*0.5 -> 0.0505 | Q5: =O5*1.5 -> 0.1515 | R5: USD per kWh
A6: solar hydrogen, 25 bar | B6: 0 | C6: kilogram | D6: =$B6*O6 -> 0 | E6: =$B6*P6 -> 0 | F6: =$B6*Q6 -> 0 | N6: solar hydrogen, 25 bar | O6: 5.28 | P6: 3.24 | Q6: 7.32 | R6: USD per kg
A7: wind hydrogen, 25 bar | B7: 0 | C7: kilogram | D7: =$B7*O7 -> 0 | E7: =$B7*P7 -> 0 | F7: =$B7*Q7 -> 0 | N7: wind hydrogen, 25 bar | O7: 4.95 | P7: 3.038 | Q7: 6.863 | R7: USD per kg
A8: nitrogen gaseous | B8: 0 | C8: kilogram | D8: =$B8*O8 -> 0 | E8: =$B8*P8 -> 0 | F8: =$B8*Q8 -> 0 | N8: nitrogen gaseous | O8: =91/1000*596.2/607.5*596.2/550.8*596.2/550.8 -> 0.10463649 | P8: =O8*0.5 -> 0.052318245 | Q8: =O8*1.5 -> 0.15695473 | R8: USD per kg
A9: CO2 emissions, fossil | B9: 1.4326 | C9: kilogram | D9: =$B9*O9 -> 0 | E9: =$B9*P9 -> 0 | F9: =$B9*Q9 -> 0 | N9: CO2 emissions, fossil | O9: 0 | P9: 0 | Q9: 0 | R9: USD per kg
A10: CO2 emissions, biogenic | B10: 0 | C10: kilogram | D10: =$B10*O10 -> 0 | E10: =$B10*P10 -> 0 | F10: =$B10*Q10 -> 0 | N10: CO2 emissions, biogenic | O10: 0 | P10: 0 | Q10: 0 | R10: USD per kg
A11: CAPEX contribution | B11: - | C11: - | D11: =O13 -> 0.15594596 | E11: =D11 -> 0.15594596 | F11: =E11 -> 0.15594596
A12: Fixed costs contribution | B12: - | C12: - | D12: =O14 -> 0.079906196 | E12: =D12 -> 0.079906196 | F12: =E12 -> 0.079906196 | N12: For fossil routes
N13: CAPEX contribution | O13: =0.1331*596.2/550.8*596.2/550.8 -> 0.15594596 | P13: 0 | Q13: 0 | R13: USD2019 kg-1 ammonia
A14: Blue ammonia | D14: Cost | E14: Low | F14: High | N14: Fixed costs contribution | O14: =0.0682*596.2/550.8*596.2/550.8 -> 0.079906196 | P14: 0 | Q14: 0 | R14: USD2019 kg-1 ammonia
A15: ammonia | B15: 1 | C15: kilogram | D15: =SUM(D16:D25) -> 0.38345284 | E15: =SUM(E16:E25) -> 0.3096525 | F15: =SUM(F16:F25) -> 0.45725318
A16: natural gas, feedstock | B16: 0.62178 | C16: cubic meter | D16: =$B16*O3 -> 0.076633199 | E16: =$B16*P3 -> 0.0383166 | F16: =$B16*Q3 -> 0.1149498 | N16: For green routes
A17: natural gas, heating | B17: 13.952 | C17: cubic meter | D17: =$B17*O4 -> 0.046982443 | E17: =$B17*P4 -> 0.023491221 | F17: =$B17*Q4 -> 0.070473664 | N17: CAPEX contribution | O17: =0.0799*596.2/550.8*596.2/550.8 -> 0.093614443 | P17: 0 | Q17: 0 | R17: USD2019 kg-1 ammonia
A18: electricity, from grid | B18: 0.23747564 | C18: kilowatt hour | D18: =$B18*O5 -> 0.02398504 | E18: =$B18*P5 -> 0.01199252 | F18: =$B18*Q5 -> 0.035977559 | N18: Fixed costs contribution | O18: =0.0491*596.2/550.8*596.2/550.8 -> 0.057527774 | P18: 0 | Q18: 0 | R18: USD2019 kg-1 ammonia
A19: solar hydrogen, 25 bar | B19: 0 | C19: kilogram | D19: =$B19*O6 -> 0 | E19: =$B19*P6 -> 0 | F19: =$B19*Q6 -> 0
A20: wind hydrogen, 25 bar | B20: 0 | C20: kilogram | D20: =$B20*O7 -> 0 | E20: =$B20*P7 -> 0 | F20: =$B20*Q7 -> 0
A21: nitrogen gaseous | B21: 0 | C21: kilogram | D21: =$B21*O8 -> 0 | E21: =$B21*P8 -> 0 | F21: =$B21*Q8 -> 0
A22: CO2 emissions, fossil | B22: 0.14326 | C22: kilogram | D22: =$B22*O9 -> 0 | E22: =$B22*P9 -> 0 | F22: =$B22*Q9 -> 0
A23: CO2 emissions, biogenic | B23: 0 | C23: kilogram | D23: =$B23*O10 -> 0 | E23: =$B23*P10 -> 0 | F23: =$B23*Q10 -> 0
A24: CAPEX contribution | B24: - | C24: - | D24: =O13 -> 0.15594596 | E24: =D24 -> 0.15594596 | F24: =E24 -> 0.15594596
A25: Fixed costs contribution | B25: - | C25: - | D25: =O14 -> 0.079906196 | E25: =D25 -> 0.079906196 | F25: =E25 -> 0.079906196
A27: Solar ammonia | D27: Cost | E27: Low | F27: High
A28: ammonia | B28: 1 | C28: kilogram | D28: =SUM(D29:D38) -> 1.221857 | E28: =SUM(E29:E38) -> 0.79209959 | F28: =SUM(F29:F38) -> 1.6516143
A29: natural gas, feedstock | B29: 0 | C29: cubic meter | D29: =$B29*O3 -> 0 | E29: =$B29*P3 -> 0 | F29: =$B29*Q3 -> 0
A30: natural gas, heating | B30: 0 | C30: megajoule | D30: =$B30*O4 -> 0 | E30: =$B30*P4 -> 0 | F30: =$B30*Q4 -> 0
A31: electricity, from grid | B31: 0.556 | C31: kilowatt hour | D31: =$B31*O5 -> 0.056156 | E31: =$B31*P5 -> 0.028078 | F31: =$B31*Q5 -> 0.084234
A32: solar hydrogen, 25 bar | B32: 0.176 | C32: kilogram | D32: =$B32*O6 -> 0.92928 | E32: =$B32*P6 -> 0.57024 | F32: =$B32*Q6 -> 1.28832
A33: wind hydrogen, 25 bar | B33: 0 | C33: kilogram | D33: =$B33*O7 -> 0 | E33: =$B33*P7 -> 0 | F33: =$B33*Q7 -> 0
A34: nitrogen gaseous | B34: 0.815 | C34: kilogram | D34: =$B34*O8 -> 0.085278739 | E34: =$B34*P8 -> 0.04263937 | F34: =$B34*Q8 -> 0.12791811
A35: CO2 emissions, fossil | B35: 0 | C35: kilogram | D35: =$B35*O9 -> 0 | E35: =$B35*P9 -> 0 | F35: =$B35*Q9 -> 0
A36: CO2 emissions, biogenic | B36: 0 | C36: kilogram | D36: =$B36*O10 -> 0 | E36: =$B36*P10 -> 0 | F36: =$B36*Q10 -> 0
A37: CAPEX contribution | B37: - | C37: - | D37: =O17 -> 0.093614443 | E37: =D37 -> 0.093614443 | F37: =E37 -> 0.093614443
A38: Fixed costs contribution | B38: - | C38: - | D38: =O18 -> 0.057527774 | E38: =D38 -> 0.057527774 | F38: =E38 -> 0.057527774
A40: Wind ammonia | D40: Cost | E40: Low | F40: High
A41: ammonia | B41: 1 | C41: kilogram | D41: =SUM(D42:D51) -> 1.163777 | E41: =SUM(E42:E51) -> 0.75654759 | F41: =SUM(F42:F51) -> 1.5711823
A42: natural gas, feedstock | B42: 0 | C42: cubic meter | D42: =$B42*O3 -> 0 | E42: =$B42*P3 -> 0 | F42: =$B42*Q3 -> 0
...

Sheet 2050
A1: Fossil ammonia | D1: Cost | E1: Low | F1: High | N1: Prices
A2: ammonia | B2: 1 | C2: kilogram | D2: =SUM(D3:D12) -> 0.3885093 | E2: =SUM(E3:E12) -> 0.32190085 | F2: =SUM(F3:F12) -> 0.45511775 | N2: Category | O2: Price | P2: Low | Q2: High
A3: natural gas, feedstock | B3: 0.62178 | C3: cubic meter | D3: =$B3*O3 -> 0.079655354 | E3: =$B3*P3 -> 0.039827677 | F3: =$B3*Q3 -> 0.11948303 | N3: natural gas, feedstock | O3: 0.12810858 | P3: =O3*0.5 -> 0.064054291 | Q3: =O3*1.5 -> 0.19216287 | R3: USD per m3
A4: natural gas, heating | B4: 13.952 | C4: megajoule | D4: =$B4*O4 -> 0.048835271 | E4: =$B4*P4 -> 0.024417636 | F4: =$B4*Q4 -> 0.073252907 | N4: natural gas, heating | O4: =3.50023446348733/1000 -> 0.0035002345 | P4: =O4*0.5 -> 0.0017501172 | Q4: =O4*1.5 -> 0.0052503517 | R4: USD per MJ | T4: =O4*1000 -> 3.5002345 | U4: =P4*1000 -> 1.7501172 | V4: =Q4*1000 -> 5.2503517
A5: electricity, from grid | B5: 0.049232 | C5: kilowatt hour | D5: =$B5*O5 -> 0.004726272 | E5: =$B5*P5 -> 0.002363136 | F5: =$B5*Q5 -> 0.007089408 | N5: electricity, from grid | O5: 0.096 | P5: =O5*0.5 -> 0.048 | Q5: =O5*1.5 -> 0.144 | R5: USD per kWh
A6: solar hydrogen, 25 bar | B6: 0 | C6: kilogram | D6: =$B6*O6 -> 0 | E6: =$B6*P6 -> 0 | F6: =$B6*Q6 -> 0 | N6: solar hydrogen, 25 bar | O6: 3.927 | P6: 2.533 | Q6: 5.32 | R6: USD per kg
A7: wind hydrogen, 25 bar | B7: 0 | C7: kilogram | D7: =$B7*O7 -> 0 | E7: =$B7*P7 -> 0 | F7: =$B7*Q7 -> 0 | N7: wind hydrogen, 25 bar | O7: 3.5 | P7: 2.4 | Q7: 4.6 | R7: USD per kg
A8: nitrogen gaseous | B8: 0 | C8: kilogram | D8: =$B8*O8 -> 0 | E8: =$B8*P8 -> 0 | F8: =$B8*Q8 -> 0 | N8: nitrogen gaseous | O8: =91/1000*596.2/607.5*596.2/550.8*596.2/550.8*596.2/550.8 -> 0.11326121 | P8: =O8*0.5 -> 0.056630606 | Q8: =O8*1.5 -> 0.16989182 | R8: USD per kg
A9: CO2 emissions, fossil | B9: 1.4326 | C9: kilogram | D9: =$B9*O9 -> 0 | E9: =$B9*P9 -> 0 | F9: =$B9*Q9 -> 0 | N9: CO2 emissions, fossil | O9: 0 | P9: 0 | Q9: 0 | R9: USD per kg
A10: CO2 emissions, biogenic | B10: 0 | C10: kilogram | D10: =$B10*O10 -> 0 | E10: =$B10*P10 -> 0 | F10: =$B10*Q10 -> 0 | N10: CO2 emissions, biogenic | O10: 0 | P10: 0 | Q10: 0 | R10: USD per kg
A11: CAPEX contribution | B11: - | C11: - | D11: =O13 -> 0.1687999 | E11: =D11 -> 0.1687999 | F11: =E11 -> 0.1687999
A12: Fixed costs contribution | B12: - | C12: - | D12: =O14 -> 0.086492509 | E12: =D12 -> 0.086492509 | F12: =E12 -> 0.086492509 | N12: For fossil routes
N13: CAPEX contribution | O13: =0.1331*596.2/550.8*596.2/550.8*596.2/550.8 -> 0.1687999 | P13: 0 | Q13: 0 | R13: USD2019 kg-1 ammonia
A14: Blue ammonia | D14: Cost | E14: Low | F14: High | N14: Fixed costs contribution | O14: =0.0682*596.2/550.8*596.2/550.8*596.2/550.8 -> 0.086492509 | P14: 0 | Q14: 0 | R14: USD2019 kg-1 ammonia
A15: ammonia | B15: 1 | C15: kilogram | D15: =SUM(D16:D25) -> 0.40658069 | E15: =SUM(E16:E25) -> 0.33093655 | F15: =SUM(F16:F25) -> 0.48222483
A16: natural gas, feedstock | B16: 0.62178 | C16: cubic meter | D16: =$B16*O3 -> 0.079655354 | E16: =$B16*P3 -> 0.039827677 | F16: =$B16*Q3 -> 0.11948303 | N16: For green routes
A17: natural gas, heating | B17: 13.952 | C17: cubic meter | D17: =$B17*O4 -> 0.048835271 | E17: =$B17*P4 -> 0.024417636 | F17: =$B17*Q4 -> 0.073252907 | N17: CAPEX contribution | O17: =0.0799*596.2/550.8*596.2/550.8*596.2/550.8 -> 0.10133067 | P17: 0 | Q17: 0 | R17: USD2019 kg-1 ammonia
A18: electricity, from grid | B18: 0.23747564 | C18: kilowatt hour | D18: =$B18*O5 -> 0.022797661 | E18: =$B18*P5 -> 0.011398831 | F18: =$B18*Q5 -> 0.034196492 | N18: Fixed costs contribution | O18: =0.0491*596.2/550.8*596.2/550.8*596.2/550.8 -> 0.062269534 | P18: 0 | Q18: 0 | R18: USD2019 kg-1 ammonia
A19: solar hydrogen, 25 bar | B19: 0 | C19: kilogram | D19: =$B19*O6 -> 0 | E19: =$B19*P6 -> 0 | F19: =$B19*Q6 -> 0
A20: wind hydrogen, 25 bar | B20: 0 | C20: kilogram | D20: =$B20*O7 -> 0 | E20: =$B20*P7 -> 0 | F20: =$B20*Q7 -> 0
A21: nitrogen gaseous | B21: 0 | C21: kilogram | D21: =$B21*O8 -> 0 | E21: =$B21*P8 -> 0 | F21: =$B21*Q8 -> 0
A22: CO2 emissions, fossil | B22: 0.14326 | C22: kilogram | D22: =$B22*O9 -> 0 | E22: =$B22*P9 -> 0 | F22: =$B22*Q9 -> 0
A23: CO2 emissions, biogenic | B23: 0 | C23: kilogram | D23: =$B23*O10 -> 0 | E23: =$B23*P10 -> 0 | F23: =$B23*Q10 -> 0
A24: CAPEX contribution | B24: - | C24: - | D24: =O13 -> 0.1687999 | E24: =D24 -> 0.1687999 | F24: =E24 -> 0.1687999
A25: Fixed costs contribution | B25: - | C25: - | D25: =O14 -> 0.086492509 | E25: =D25 -> 0.086492509 | F25: =E25 -> 0.086492509
A27: Solar ammonia | D27: Cost | E27: Low | F27: High
A28: ammonia | B28: 1 | C28: kilogram | D28: =SUM(D29:D38) -> 1.0004361 | E28: =SUM(E29:E38) -> 0.68225014 | F28: =SUM(F29:F38) -> 1.318446
A29: natural gas, feedstock | B29: 0 | C29: cubic meter | D29: =$B29*O3 -> 0 | E29: =$B29*P3 -> 0 | F29: =$B29*Q3 -> 0
A30: natural gas, heating | B30: 0 | C30: megajoule | D30: =$B30*O4 -> 0 | E30: =$B30*P4 -> 0 | F30: =$B30*Q4 -> 0
A31: electricity, from grid | B31: 0.556 | C31: kilowatt hour | D31: =$B31*O5 -> 0.053376 | E31: =$B31*P5 -> 0.026688 | F31: =$B31*Q5 -> 0.080064
A32: solar hydrogen, 25 bar | B32: 0.176 | C32: kilogram | D32: =$B32*O6 -> 0.691152 | E32: =$B32*P6 -> 0.445808 | F32: =$B32*Q6 -> 0.93632
A33: wind hydrogen, 25 bar | B33: 0 | C33: kilogram | D33: =$B33*O7 -> 0 | E33: =$B33*P7 -> 0 | F33: =$B33*Q7 -> 0
A34: nitrogen gaseous | B34: 0.815 | C34: kilogram | D34: =$B34*O8 -> 0.092307887 | E34: =$B34*P8 -> 0.046153944 | F34: =$B34*Q8 -> 0.13846183
A35: CO2 emissions, fossil | B35: 0 | C35: kilogram | D35: =$B35*O9 -> 0 | E35: =$B35*P9 -> 0 | F35: =$B35*Q9 -> 0
A36: CO2 emissions, biogenic | B36: 0 | C36: kilogram | D36: =$B36*O10 -> 0 | E36: =$B36*P10 -> 0 | F36: =$B36*Q10 -> 0
A37: CAPEX contribution | B37: - | C37: - | D37: =O17 -> 0.10133067 | E37: =D37 -> 0.10133067 | F37: =E37 -> 0.10133067
A38: Fixed costs contribution | B38: - | C38: - | D38: =O18 -> 0.062269534 | E38: =D38 -> 0.062269534 | F38: =E38 -> 0.062269534
A40: Wind ammonia | D40: Cost | E40: Low | F40: High
A41: ammonia | B41: 1 | C41: kilogram | D41: =SUM(D42:D51) -> 0.92528409 | E41: =SUM(E42:E51) -> 0.65884214 | F41: =SUM(F42:F51) -> 1.191726
A42: natural gas, feedstock | B42: 0 | C42: cubic meter | D42: =$B42*O3 -> 0 | E42: =$B42*P3 -> 0 | F42: =$B42*Q3 -> 0
...

Sheet H2 and CO2 costs
B2: 2030 | C2: 2040 | D2: 2050
A3: CAPEX | B3: 750 | C3: 500 | D3: 250
A4: Solar electricity | B4: 58 | C4: 48 | D4: 38
A5: Solar hydrogen | B5: =AVERAGE(B6:B7) -> 6.67 | C5: =AVERAGE(C6:C7) -> 5.28 | D5: =AVERAGE(D6:D7) -> 3.9266667
A6: Solar hydrogen low | B6: =B4*3.5/50 -> 4.06 | C6: =C4*2.7/40 -> 3.24 | D6: =2*D4/30 -> 2.5333333
A7: Solar hydrogen high | B7: =B4*8/50 -> 9.28 | C7: =C4*6.1/40 -> 7.32 | D7: =4.2*D4/30 -> 5.32
A8: Wind electricity | B8: 50 | C8: 45 | D8: 40
A9: Wind hydrogen | B9: =AVERAGE(B10:B11) -> 5.75 | C9: =AVERAGE(C10:C11) -> 4.95 | D9: =AVERAGE(D10:D11) -> 3.5
A10: Wind hydrogen low | B10: 3.5 | C10: =C8*2.7/40 -> 3.0375 | D10: 2.4
A11: Wind hydrogen high | B11: 8 | C11: =C8*6.1/40 -> 6.8625 | D11: 4.6
B14: Avg | C14: Low | D14: High
A15: 2020 | B15: 0.36153846 | C15: 0.26923077 | D15: 0.62307692
A16: 2030 | B16: 0.19230769 | C16: 0.12307692 | D16: 0.46923077
A17: 2040 | B17: =AVERAGE(B16,B18) -> 0.15769231 | C17: =AVERAGE(C16,C18) -> 0.10769231 | D17: =AVERAGE(D16,D18) -> 0.43076923
A18: 2050 | B18: 0.12307692 | C18: 0.092307692 | D18: 0.39230769

Sheet Overall
B1: Fossil 2020 | C1: Fossil 2030 | D1: Fossil 2040 | E1: Fossil 2050 | F1: Blue 2020 | G1: Blue 2030 | H1: Blue 2040 | I1: Blue 2050 | J1: Solar 2020 | K1: Solar 2030 | L1: Solar 2040 | M1: Solar 2050 | N1: Wind 2020 | O1: Wind 2030 | P1: Wind 2040 | Q1: Wind 2050
A2: natural gas, feedstock | B2: ='2020'!D3 -> 0.044684711 | C2: ='2030'!D3 -> 0.072099968 | D2: ='2040'!D3 -> 0.076633199 | E2: ='2050'!D3 -> 0.079655354 | F2: ='2020'!D16 -> 0.044684711 | G2: ='2030'!D16 -> 0.072099968 | H2: ='2040'!D16 -> 0.076633199 | I2: ='2050'!D16 -> 0.079655354 | J2: ='2020'!D29 -> 0 | K2: ='2030'!D29 -> 0 | L2: ='2040'!D29 -> 0 | M2: ='2050'!D29 -> 0 | N2: ='2020'!D42 -> 0 | O2: ='2030'!D42 -> 0 | P2: ='2040'!D42 -> 0 | Q2: ='2050'!D42 -> 0
A3: natural gas, heating | B3: ='2020'!D4 -> 0.027395396 | C3: ='2030'!D4 -> 0.044203199 | D3: ='2040'!D4 -> 0.046982443 | E3: ='2050'!D4 -> 0.048835271 | F3: ='2020'!D17 -> 0.027395396 | G3: ='2030'!D17 -> 0.044203199 | H3: ='2040'!D17 -> 0.046982443 | I3: ='2050'!D17 -> 0.048835271 | J3: ='2020'!D30 -> 0 | K3: ='2030'!D30 -> 0 | L3: ='2040'!D30 -> 0 | M3: ='2050'!D30 -> 0 | N3: ='2020'!D43 -> 0 | O3: ='2030'!D43 -> 0 | P3: ='2040'!D43 -> 0 | Q3: ='2050'!D43 -> 0
A4: electricity, from grid | B4: ='2020'!D5 -> 0.005120128 | C4: ='2030'!D5 -> 0.005070896 | D4: ='2040'!D5 -> 0.004972432 | E4: ='2050'!D5 -> 0.004726272 | F4: ='2020'!D18 -> 0.024697467 | G4: ='2030'!D18 -> 0.024459991 | H4: ='2040'!D18 -> 0.02398504 | I4: ='2050'!D18 -> 0.022797661 | J4: ='2020'!D31 -> 0.057824 | K4: ='2030'!D31 -> 0.057268 | L4: ='2040'!D31 -> 0.056156 | M4: ='2050'!D31 -> 0.053376 | N4: ='2020'!D44 -> 0.057824 | O4: ='2030'!D44 -> 0.057268 | P4: ='2040'!D44 -> 0.056156 | Q4: ='2050'!D44 -> 0.053376
A5: solar hydrogen, 25 bar | B5: ='2020'!D6 -> 0 | C5: ='2030'!D6 -> 0 | D5: ='2040'!D6 -> 0 | E5: ='2050'!D6 -> 0 | F5: ='2020'!D19 -> 0 | G5: ='2030'!D19 -> 0 | H5: ='2040'!D19 -> 0 | I5: ='2050'!D19 -> 0 | J5: ='2020'!D32 -> 1.62272 | K5: ='2030'!D32 -> 1.17392 | L5: ='2040'!D32 -> 0.92928 | M5: ='2050'!D32 -> 0.691152 | N5: ='2020'!D45 -> 0 | O5: ='2030'!D45 -> 0 | P5: ='2040'!D45 -> 0 | Q5: ='2050'!D45 -> 0
A6: wind hydrogen, 25 bar | B6: ='2020'!D7 -> 0 | C6: ='2030'!D7 -> 0 | D6: ='2040'!D7 -> 0 | E6: ='2050'!D7 -> 0 | F6: ='2020'!D20 -> 0 | G6: ='2030'!D20 -> 0 | H6: ='2040'!D20 -> 0 | I6: ='2050'!D20 -> 0 | J6: ='2020'!D33 -> 0 | K6: ='2030'!D33 -> 0 | L6: ='2040'!D33 -> 0 | M6: ='2050'!D33 -> 0 | N6: ='2020'!D46 -> 1.21088 | O6: ='2030'!D46 -> 1.012 | P6: ='2040'!D46 -> 0.8712 | Q6: ='2050'!D46 -> 0.616
A7: nitrogen gaseous | B7: ='2020'!D8 -> 0 | C7: ='2030'!D8 -> 0 | D7: ='2040'!D8 -> 0 | E7: ='2050'!D8 -> 0 | F7: ='2020'!D21 -> 0 | G7: ='2030'!D21 -> 0 | H7: ='2040'!D21 -> 0 | I7: ='2050'!D21 -> 0 | J7: ='2020'!D34 -> 0.07278547 | K7: ='2030'!D34 -> 0.078784853 | L7: ='2040'!D34 -> 0.085278739 | M7: ='2050'!D34 -> 0.092307887 | N7: ='2020'!D47 -> 0.07278547 | O7: ='2030'!D47 -> 0.078784853 | P7: ='2040'!D47 -> 0.085278739 | Q7: ='2050'!D47 -> 0.092307887
A8: CO2 emissions, fossil | B8: ='2020'!D9 -> 0 | C8: ='2030'!D9 -> 0 | D8: ='2040'!D9 -> 0 | E8: ='2050'!D9 -> 0 | F8: ='2020'!D22 -> 0 | G8: ='2030'!D22 -> 0 | H8: ='2040'!D22 -> 0 | I8: ='2050'!D22 -> 0 | J8: ='2020'!D35 -> 0 | K8: ='2030'!D35 -> 0 | L8: ='2040'!D35 -> 0 | M8: ='2050'!D35 -> 0 | N8: ='2020'!D48 -> 0 | O8: ='2030'!D48 -> 0 | P8: ='2040'!D48 -> 0 | Q8: ='2050'!D48 -> 0
A9: CO2 emissions, biogenic | B9: ='2020'!D10 -> 0 | C9: ='2030'!D10 -> 0 | D9: ='2040'!D10 -> 0 | E9: ='2050'!D10 -> 0 | F9: ='2020'!D23 -> 0 | G9: ='2030'!D23 -> 0 | H9: ='2040'!D23 -> 0 | I9: ='2050'!D23 -> 0 | J9: ='2020'!D36 -> 0 | K9: ='2030'!D36 -> 0 | L9: ='2040'!D36 -> 0 | M9: ='2050'!D36 -> 0 | N9: ='2020'!D49 -> 0 | O9: ='2030'!D49 -> 0 | P9: ='2040'!D49 -> 0 | Q9: ='2050'!D49 -> 0
A10: CAPEX contribution | B10: ='2020'!D11 -> 0.1331 | C10: ='2030'!D11 -> 0.14407084 | D10: ='2040'!D11 -> 0.15594596 | E10: ='2050'!D11 -> 0.1687999 | F10: ='2020'!D24 -> 0.1331 | G10: ='2030'!D24 -> 0.14407084 | H10: ='2040'!D24 -> 0.15594596 | I10: ='2050'!D24 -> 0.1687999 | J10: ='2020'!D37 -> 0.0799 | K10: ='2030'!D37 -> 0.086485802 | L10: ='2040'!D37 -> 0.093614443 | M10: ='2050'!D37 -> 0.10133067 | N10: ='2020'!D50 -> 0.0799 | O10: ='2030'!D50 -> 0.086485802 | P10: ='2040'!D50 -> 0.093614443 | Q10: ='2050'!D50 -> 0.10133067
A11: Fixed costs contribution | B11: ='2020'!D12 -> 0.0682 | C11: ='2030'!D12 -> 0.073821423 | D11: ='2040'!D12 -> 0.079906196 | E11: ='2050'!D12 -> 0.086492509 | F11: ='2020'!D25 -> 0.0682 | G11: ='2030'!D25 -> 0.073821423 | H11: ='2040'!D25 -> 0.079906196 | I11: ='2050'!D25 -> 0.086492509 | J11: ='2020'!D38 -> 0.0491 | K11: ='2030'!D38 -> 0.053147095 | L11: ='2040'!D38 -> 0.057527774 | M11: ='2050'!D38 -> 0.062269534 | N11: ='2020'!D51 -> 0.0491 | O11: ='2030'!D51 -> 0.053147095 | P11: ='2040'!D51 -> 0.057527774 | Q11: ='2050'!D51 -> 0.062269534
A12: Low | B12: ='2020'!E2 -> 0.23990012 | C12: ='2030'!E2 -> 0.2785793 | D12: ='2040'!E2 -> 0.3001462 | E12: ='2050'!E2 -> 0.32190085 | F12: ='2020'!E15 -> 0.24968879 | G12: ='2030'!E15 -> 0.28827384 | H12: ='2040'!E15 -> 0.3096525 | I12: ='2050'!E15 -> 0.33093655 | J12: ='2020'!E28 -> 1.6621447 | K12: ='2030'!E28 -> 0.92221932 | L12: ='2040'!E28 -> 0.79209959 | M12: ='2050'!E28 -> 0.68225014 | N12: ='2020'!E41 -> 1.1147847 | O12: ='2030'!E41 -> 0.82365932 | P12: ='2040'!E41 -> 0.75654759 | Q12: ='2050'!E41 -> 0.65884214
A13: High | B13: ='2020'!F2 -> 0.31710035 | C13: ='2030'!F2 -> 0.39995336 | D13: ='2040'!F2 -> 0.42873427 | E13: ='2050'!F2 -> 0.45511775 | F13: ='2020'!F15 -> 0.34646636 | G13: ='2030'!F15 -> 0.429037 | H13: ='2040'!F15 -> 0.45725318 | I13: ='2050'!F15 -> 0.48222483 | J13: ='2020'!F28 -> 3.1233142 | K13: ='2030'!F28 -> 1.9769922 | L13: ='2040'!F28 -> 1.6516143 | M13: ='2050'!F28 -> 1.318446 | N13: ='2020'!F41 -> 1.8173942 | O13: ='2030'!F41 -> 1.7517122 | P13: ='2040'!F41 -> 1.5711823 | Q13: ='2050'!F41 -> 1.191726
