Workbook

Sheet 2020
A1: Fossil methanol | D1: Cost | E1: Low | F1: High | N1: Prices
A2: methanol | B2: 1 | C2: kilogram | D2: =SUM(D3:D12) -> 0.18006128 | E2: =SUM(E3:E12) -> 0.1305229 | F2: =SUM(F3:F12) -> 0.25748312 | N2: Category | O2: Price | P2: Low | Q2: High
A3: natural gas, feedstock | B3: 0.65179 | C3: cubic meter | D3: =$B3*O3 -> 0.073373147 | E3: =$B3*P3 -> 0.035754723 | F3: =$B3*Q3 -> 0.13260647 | N3: natural gas, feedstock | O3: =144.88/1000*0.777 -> 0.11257176 | P3: =70.6/1000*0.777 -> 0.0548562 | Q3: =261.84/1000*0.777 -> 0.20344968 | R3: USD per m3
A4: natural gas, heating | B4: 6.93 | C4: megajoule | D4: =$B4*O4 -> 0.021316739 | E4: =$B4*P4 -> 0.010387643 | F4: =$B4*Q4 -> 0.038525503 | N4: natural gas, heating | O4: =144.88/1000/47.1 -> 0.0030760085 | P4: =70.6/1000/47.1 -> 0.0014989384 | Q4: =261.84/1000/47.1 -> 0.0055592357 | R4: USD per MJ
A5: electricity, from grid | B5: 0.074 | C5: kilowatt hour | D5: =$B5*O5 -> 0.00225256 | E5: =$B5*P5 -> 0.0012617 | F5: =$B5*Q5 -> 0.00323232 | N5: electricity, from grid | O5: =30.44/1000 -> 0.03044 | P5: =17.05/1000 -> 0.01705 | Q5: =43.68/1000 -> 0.04368 | R5: USD per kWh
A6: solar hydrogen, 25 bar | B6: 0 | C6: kilogram | D6: =$B6*O6 -> 0 | E6: =$B6*P6 -> 0 | F6: =$B6*Q6 -> 0 | N6: solar hydrogen, 25 bar | O6: 3.2 | P6: 2.7 | Q6: 4 | R6: USD per kg
A7: wind hydrogen, 25 bar | B7: 0 | C7: kilogram | D7: =$B7*O7 -> 0 | E7: =$B7*P7 -> 0 | F7: =$B7*Q7 -> 0 | N7: wind hydrogen, 25 bar | O7: 3 | P7: 2.2 | Q7: 4 | R7: USD per kg
A8: carbon dioxide gaseous | B8: 0 | C8: kilogram | D8: =$B8*O8 -> 0 | E8: =$B8*P8 -> 0 | F8: =$B8*Q8 -> 0 | N8: carbon dioxide gaseous | O8: =453/1000 -> 0.453 | P8: =453/1000 -> 0.453 | Q8: =453/1000 -> 0.453 | R8: USD per kg
A9: CO2 emissions, fossil | B9: 0 | C9: kilogram | D9: =$B9*O9 -> 0 | E9: =$B9*P9 -> 0 | F9: =$B9*Q9 -> 0 | N9: CO2 emissions, fossil | O9: 0 | P9: 0 | Q9: 0 | R9: USD per kg
A10: CO2 emissions, biogenic | B10: 0 | C10: kilogram | D10: =$B10*O10 -> 0 | E10: =$B10*P10 -> 0 | F10: =$B10*Q10 -> 0 | N10: CO2 emissions, biogenic | O10: 0 | P10: 0 | Q10: 0 | R10: USD per kg
A11: CAPEX contribution | B11: - | C11: - | D11: =O13 -> 0.054958354 | E11: =D11 -> 0.054958354 | F11: =E11 -> 0.054958354
A12: Fixed costs contribution | B12: - | C12: - | D12: =O14 -> 0.028160479 | E12: =D12 -> 0.028160479 | F12: =E12 -> 0.028160479 | N12: For fossil routes
N13: CAPEX contribution | O13: =0.056*596.2/607.5 -> 0.054958354 | P13: 0 | Q13: 0 | R13: USD2019 kg-1 methanol
A14: Blue methanol | D14: Cost | E14: Low | F14: High | N14: Fixed costs contribution | O14: =0.0286942148760331*596.2/607.5 -> 0.028160479 | P14: 0 | Q14: 0 | R14: USD2019 kg-1 methanol
A15: methanol | B15: 1 | C15: kilogram | D15: =SUM(D16:D25) -> 0.185023 | E15: =SUM(E16:E25) -> 0.13330205 | F15: =SUM(F16:F25) -> 0.26460296
A16: natural gas, feedstock | B16: 0.65179 | C16: cubic meter | D16: =$B16*O3 -> 0.073373147 | E16: =$B16*P3 -> 0.035754723 | F16: =$B16*Q3 -> 0.13260647 | N16: For green routes
A17: natural gas, heating | B17: 6.93 | C17: cubic meter | D17: =$B17*O4 -> 0.021316739 | E17: =$B17*P4 -> 0.010387643 | F17: =$B17*Q4 -> 0.038525503 | N17: CAPEX contribution | O17: =0.092*596.2/607.5 -> 0.090288724 | P17: 0 | Q17: 0 | R17: USD2019 kg-1 methanol
A18: electricity, from grid | B18: 0.237 | C18: kilowatt hour | D18: =$B18*O5 -> 0.00721428 | E18: =$B18*P5 -> 0.00404085 | F18: =$B18*Q5 -> 0.01035216 | N18: Fixed costs contribution | O18: =0.0471404958677686*596.2/607.5 -> 0.046263644 | P18: 0 | Q18: 0 | R18: USD2019 kg-1 methanol
A19: solar hydrogen, 25 bar | B19: 0 | C19: kilogram | D19: =$B19*O6 -> 0 | E19: =$B19*P6 -> 0 | F19: =$B19*Q6 -> 0
A20: wind hydrogen, 25 bar | B20: 0 | C20: kilogram | D20: =$B20*O7 -> 0 | E20: =$B20*P7 -> 0 | F20: =$B20*Q7 -> 0
A21: carbon dioxide gaseous | B21: 0 | C21: kilogram | D21: =$B21*O8 -> 0 | E21: =$B21*P8 -> 0 | F21: =$B21*Q8 -> 0
A22: CO2 emissions, fossil | B22: 0 | C22: kilogram | D22: =$B22*O9 -> 0 | E22: =$B22*P9 -> 0 | F22: =$B22*Q9 -> 0
A23: CO2 emissions, biogenic | B23: 0 | C23: kilogram | D23: =$B23*O10 -> 0 | E23: =$B23*P10 -> 0 | F23: =$B23*Q10 -> 0
A24: CAPEX contribution | B24: - | C24: - | D24: =O13 -> 0.054958354 | E24: =D24 -> 0.054958354 | F24: =E24 -> 0.054958354
A25: Fixed costs contribution | B25: - | C25: - | D25: =O14 -> 0.028160479 | E25: =D25 -> 0.028160479 | F25: =E25 -> 0.028160479
A27: Solar methanol | D27: Cost | E27: Low | F27: High
A28: methanol | B28: 1 | C28: kilogram | D28: =SUM(D29:D38) -> 1.3562558 | E28: =SUM(E29:E38) -> 1.2827123 | F28: =SUM(F29:F38) -> 1.4714465
A29: natural gas, feedstock | B29: 0 | C29: cubic meter | D29: =$B29*O3 -> 0 | E29: =$B29*P3 -> 0 | F29: =$B29*Q3 -> 0
A30: natural gas, heating | B30: 0 | C30: megajoule | D30: =$B30*O4 -> 0 | E30: =$B30*P4 -> 0 | F30: =$B30*Q4 -> 0
A31: electricity, from grid | B31: 0.30289532 | C31: kilowatt hour | D31: =$B31*O5 -> 0.0092201336 | E31: =$B31*P5 -> 0.0051643653 | F31: =$B31*Q5 -> 0.013230468
A32: solar hydrogen, 25 bar | B32: 0.1389755 | C32: kilogram | D32: =$B32*O6 -> 0.4447216 | E32: =$B32*P6 -> 0.37523385 | F32: =$B32*Q6 -> 0.555902
A33: wind hydrogen, 25 bar | B33: 0 | C33: kilogram | D33: =$B33*O7 -> 0 | E33: =$B33*P7 -> 0 | F33: =$B33*Q7 -> 0
A34: carbon dioxide gaseous | B34: 1.6904232 | C34: kilogram | D34: =$B34*O8 -> 0.76576169 | E34: =$B34*P8 -> 0.76576169 | F34: =$B34*Q8 -> 0.76576169
A35: CO2 emissions, fossil | B35: 0 | C35: kilogram | D35: =$B35*O9 -> 0 | E35: =$B35*P9 -> 0 | F35: =$B35*Q9 -> 0
A36: CO2 emissions, biogenic | B36: 0 | C36: kilogram | D36: =$B36*O10 -> 0 | E36: =$B36*P10 -> 0 | F36: =$B36*Q10 -> 0
A37: CAPEX contribution | B37: - | C37: - | D37: =O17 -> 0.090288724 | E37: =D37 -> 0.090288724 | F37: =E37 -> 0.090288724
A38: Fixed costs contribution | B38: - | C38: - | D38: =O18 -> 0.046263644 | E38: =D38 -> 0.046263644 | F38: =E38 -> 0.046263644
A40: Wind methanol | D40: Cost | E40: Low | F40: High
A41: methanol | B41: 1 | C41: kilogram | D41: =SUM(D42:D51) -> 1.3284607 | E41: =SUM(E42:E51) -> 1.2132245 | F41: =SUM(F42:F51) -> 1.4714465
A42: natural gas, feedstock | B42: 0 | C42: cubic meter | D42: =$B42*O3 -> 0 | E42: =$B42*P3 -> 0 | F42: =$B42*Q3 -> 0
...

Sheet 2030
A1: Fossil methanol | D1: Cost | E1: Low | F1: High | N1: Prices
A2: methanol | B2: 1 | C2: kilogram | D2: =SUM(D3:D12) -> 0.5557113 | E2: =SUM(E3:E12) -> 0.13737402 | F2: =SUM(F3:F12) -> 2.1700701 | N2: Category | O2: Price | P2: Low | Q2: High
A3: natural gas, feedstock | B3: 0.65179 | C3: cubic meter | D3: =$B3*O3 -> 0.35532395 | E3: =$B3*P3 -> 0.035754723 | F3: =$B3*Q3 -> 1.5849116 | N3: natural gas, feedstock | O3: =701.61/1000*0.777 -> 0.54515097 | P3: =70.6/1000*0.777 -> 0.0548562 | Q3: =3129.51/1000*0.777 -> 2.4316293 | R3: USD per m3
A4: natural gas, heating | B4: 6.93 | C4: megajoule | D4: =$B4*O4 -> 0.10323052 | E4: =$B4*P4 -> 0.010387643 | F4: =$B4*Q4 -> 0.46045657 | N4: natural gas, heating | O4: =701.61/1000/47.1 -> 0.014896178 | P4: =70.6/1000/47.1 -> 0.0014989384 | Q4: =3129.51/1000/47.1 -> 0.066443949 | R4: USD per MJ
A5: electricity, from grid | B5: 0.074 | C5: kilowatt hour | D5: =$B5*O5 -> 0.00718688 | E5: =$B5*P5 -> 0.0012617 | F5: =$B5*Q5 -> 0.0347319 | N5: electricity, from grid | O5: =97.12/1000 -> 0.09712 | P5: =17.05/1000 -> 0.01705 | Q5: =469.35/1000 -> 0.46935 | R5: USD per kWh
A6: solar hydrogen, 25 bar | B6: 0 | C6: kilogram | D6: =$B6*O6 -> 0 | E6: =$B6*P6 -> 0 | F6: =$B6*Q6 -> 0 | N6: solar hydrogen, 25 bar | O6: 2.5 | P6: 1.8 | Q6: 2.7 | R6: USD per kg
A7: wind hydrogen, 25 bar | B7: 0 | C7: kilogram | D7: =$B7*O7 -> 0 | E7: =$B7*P7 -> 0 | F7: =$B7*Q7 -> 0 | N7: wind hydrogen, 25 bar | O7: 2.5 | P7: 1.8 | Q7: 3 | R7: USD per kg
A8: carbon dioxide gaseous | B8: 0 | C8: kilogram | D8: =$B8*O8 -> 0 | E8: =$B8*P8 -> 0 | F8: =$B8*Q8 -> 0 | N8: carbon dioxide gaseous | O8: =373.599/1000 -> 0.373599 | P8: =373.599/1000 -> 0.373599 | Q8: =373.599/1000 -> 0.373599 | R8: USD per kg
A9: CO2 emissions, fossil | B9: 0 | C9: kilogram | D9: =$B9*O9 -> 0 | E9: =$B9*P9 -> 0 | F9: =$B9*Q9 -> 0 | N9: CO2 emissions, fossil | O9: 0 | P9: 0 | Q9: 0 | R9: USD per kg
A10: CO2 emissions, biogenic | B10: 0 | C10: kilogram | D10: =$B10*O10 -> 0 | E10: =$B10*P10 -> 0 | F10: =$B10*Q10 -> 0 | N10: CO2 emissions, biogenic | O10: 0 | P10: 0 | Q10: 0 | R10: USD per kg
A11: CAPEX contribution | B11: - | C11: - | D11: =O13 -> 0.059488327 | E11: =D11 -> 0.059488327 | F11: =E11 -> 0.059488327
A12: Fixed costs contribution | B12: - | C12: - | D12: =O14 -> 0.030481622 | E12: =D12 -> 0.030481622 | F12: =E12 -> 0.030481622 | N12: For fossil routes
N13: CAPEX contribution | O13: =0.056*596.2/607.5*596.2/550.8 -> 0.059488327 | P13: 0 | Q13: 0 | R13: USD2019 kg-1 methanol
A14: Blue methanol | D14: Cost | E14: Low | F14: High | N14: Fixed costs contribution | O14: =0.0286942148760331*596.2/607.5*596.2/550.8 -> 0.030481622 | P14: 0 | Q14: 0 | R14: USD2019 kg-1 methanol
A15: methanol | B15: 1 | C15: kilogram | D15: =SUM(D16:D25) -> 0.57154186 | E15: =SUM(E16:E25) -> 0.14015317 | F15: =SUM(F16:F25) -> 2.2465741
A16: natural gas, feedstock | B16: 0.65179 | C16: cubic meter | D16: =$B16*O3 -> 0.35532395 | E16: =$B16*P3 -> 0.035754723 | F16: =$B16*Q3 -> 1.5849116 | N16: For green routes
A17: natural gas, heating | B17: 6.93 | C17: cubic meter | D17: =$B17*O4 -> 0.10323052 | E17: =$B17*P4 -> 0.010387643 | F17: =$B17*Q4 -> 0.46045657 | N17: CAPEX contribution | O17: =0.092*596.2/607.5*596.2/550.8 -> 0.097730823 | P17: 0 | Q17: 0 | R17: USD2019 kg-1 methanol
A18: electricity, from grid | B18: 0.237 | C18: kilowatt hour | D18: =$B18*O5 -> 0.02301744 | E18: =$B18*P5 -> 0.00404085 | F18: =$B18*Q5 -> 0.11123595 | N18: Fixed costs contribution | O18: =0.0471404958677686*596.2/607.5*596.2/550.8 -> 0.050076951 | P18: 0 | Q18: 0 | R18: USD2019 kg-1 methanol
A19: solar hydrogen, 25 bar | B19: 0 | C19: kilogram | D19: =$B19*O6 -> 0 | E19: =$B19*P6 -> 0 | F19: =$B19*Q6 -> 0
A20: wind hydrogen, 25 bar | B20: 0 | C20: kilogram | D20: =$B20*O7 -> 0 | E20: =$B20*P7 -> 0 | F20: =$B20*Q7 -> 0
A21: carbon dioxide gaseous | B21: 0 | C21: kilogram | D21: =$B21*O8 -> 0 | E21: =$B21*P8 -> 0 | F21: =$B21*Q8 -> 0
A22: CO2 emissions, fossil | B22: 0 | C22: kilogram | D22: =$B22*O9 -> 0 | E22: =$B22*P9 -> 0 | F22: =$B22*Q9 -> 0
A23: CO2 emissions, biogenic | B23: 0 | C23: kilogram | D23: =$B23*O10 -> 0 | E23: =$B23*P10 -> 0 | F23: =$B23*Q10 -> 0
A24: CAPEX contribution | B24: - | C24: - | D24: =O13 -> 0.059488327 | E24: =D24 -> 0.059488327 | F24: =E24 -> 0.059488327
A25: Fixed costs contribution | B25: - | C25: - | D25: =O14 -> 0.030481622 | E25: =D25 -> 0.030481622 | F25: =E25 -> 0.030481622
A27: Solar methanol | D27: Cost | E27: Low | F27: High
A28: methanol | B28: 1 | C28: kilogram | D28: =SUM(D29:D38) -> 1.1562041 | E28: =SUM(E29:E38) -> 1.0346684 | F28: =SUM(F29:F38) -> 1.2967459
A29: natural gas, feedstock | B29: 0 | C29: cubic meter | D29: =$B29*O3 -> 0 | E29: =$B29*P3 -> 0 | F29: =$B29*Q3 -> 0
A30: natural gas, heating | B30: 0 | C30: megajoule | D30: =$B30*O4 -> 0 | E30: =$B30*P4 -> 0 | F30: =$B30*Q4 -> 0
A31: electricity, from grid | B31: 0.30289532 | C31: kilowatt hour | D31: =$B31*O5 -> 0.029417194 | E31: =$B31*P5 -> 0.0051643653 | F31: =$B31*Q5 -> 0.14216392
A32: solar hydrogen, 25 bar | B32: 0.1389755 | C32: kilogram | D32: =$B32*O6 -> 0.34743875 | E32: =$B32*P6 -> 0.2501559 | F32: =$B32*Q6 -> 0.37523385
A33: wind hydrogen, 25 bar | B33: 0 | C33: kilogram | D33: =$B33*O7 -> 0 | E33: =$B33*P7 -> 0 | F33: =$B33*Q7 -> 0
A34: carbon dioxide gaseous | B34: 1.6904232 | C34: kilogram | D34: =$B34*O8 -> 0.6315404 | E34: =$B34*P8 -> 0.6315404 | F34: =$B34*Q8 -> 0.6315404
A35: CO2 emissions, fossil | B35: 0 | C35: kilogram | D35: =$B35*O9 -> 0 | E35: =$B35*P9 -> 0 | F35: =$B35*Q9 -> 0
A36: CO2 emissions, biogenic | B36: 0 | C36: kilogram | D36: =$B36*O10 -> 0 | E36: =$B36*P10 -> 0 | F36: =$B36*Q10 -> 0
A37: CAPEX contribution | B37: - | C37: - | D37: =O17 -> 0.097730823 | E37: =D37 -> 0.097730823 | F37: =E37 -> 0.097730823
A38: Fixed costs contribution | B38: - | C38: - | D38: =O18 -> 0.050076951 | E38: =D38 -> 0.050076951 | F38: =E38 -> 0.050076951
A40: Wind methanol | D40: Cost | E40: Low | F40: High
A41: methanol | B41: 1 | C41: kilogram | D41: =SUM(D42:D51) -> 1.1562041 | E41: =SUM(E42:E51) -> 1.0346684 | F41: =SUM(F42:F51) -> 1.3384386
A42: natural gas, feedstock | B42: 0 | C42: cubic meter | D42: =$B42*O3 -> 0 | E42: =$B42*P3 -> 0 | F42: =$B42*Q3 -> 0
...

Sheet 2040
A1: Fossil methanol | D1: Cost | E1: Low | F1: High | N1: Prices
A2: methanol | B2: 1 | C2: kilogram | D2: =SUM(D3:D12) -> 0.56312712 | E2: =SUM(E3:E12) -> 0.14478984 | F2: =SUM(F3:F12) -> 2.1774859 | N2: Category | O2: Price | P2: Low | Q2: High
A3: natural gas, feedstock | B3: 0.65179 | C3: cubic meter | D3: =$B3*O3 -> 0.35532395 | E3: =$B3*P3 -> 0.035754723 | F3: =$B3*Q3 -> 1.5849116 | N3: natural gas, feedstock | O3: =701.61/1000*0.777 -> 0.54515097 | P3: =70.6/1000*0.777 -> 0.0548562 | Q3: =3129.51/1000*0.777 -> 2.4316293 | R3: USD per m3
A4: natural gas, heating | B4: 6.93 | C4: megajoule | D4: =$B4*O4 -> 0.10323052 | E4: =$B4*P4 -> 0.010387643 | F4: =$B4*Q4 -> 0.46045657 | N4: natural gas, heating | O4: =701.61/1000/47.1 -> 0.014896178 | P4: =70.6/1000/47.1 -> 0.0014989384 | Q4: =3129.51/1000/47.1 -> 0.066443949 | R4: USD per MJ
A5: electricity, from grid | B5: 0.074 | C5: kilowatt hour | D5: =$B5*O5 -> 0.00718688 | E5: =$B5*P5 -> 0.0012617 | F5: =$B5*Q5 -> 0.0347319 | N5: electricity, from grid | O5: =97.12/1000 -> 0.09712 | P5: =17.05/1000 -> 0.01705 | Q5: =469.35/1000 -> 0.46935 | R5: USD per kWh
A6: solar hydrogen, 25 bar | B6: 0 | C6: kilogram | D6: =$B6*O6 -> 0 | E6: =$B6*P6 -> 0 | F6: =$B6*Q6 -> 0 | N6: solar hydrogen, 25 bar | O6: 1.8 | P6: 1.4 | Q6: 2.2 | R6: USD per kg
A7: wind hydrogen, 25 bar | B7: 0 | C7: kilogram | D7: =$B7*O7 -> 0 | E7: =$B7*P7 -> 0 | F7: =$B7*Q7 -> 0 | N7: wind hydrogen, 25 bar | O7: 2 | P7: 1.6 | Q7: 2.6 | R7: USD per kg
A8: carbon dioxide gaseous | B8: 0 | C8: kilogram | D8: =$B8*O8 -> 0 | E8: =$B8*P8 -> 0 | F8: =$B8*Q8 -> 0 | N8: carbon dioxide gaseous | O8: =293.931999999999/1000 -> 0.293932 | P8: =293.931999999999/1000 -> 0.293932 | Q8: =293.931999999999/1000 -> 0.293932 | R8: USD per kg
A9: CO2 emissions, fossil | B9: 0 | C9: kilogram | D9: =$B9*O9 -> 0 | E9: =$B9*P9 -> 0 | F9: =$B9*Q9 -> 0 | N9: CO2 emissions, fossil | O9: 0 | P9: 0 | Q9: 0 | R9: USD per kg
A10: CO2 emissions, biogenic | B10: 0 | C10: kilogram | D10: =$B10*O10 -> 0 | E10: =$B10*P10 -> 0 | F10: =$B10*Q10 -> 0 | N10: CO2 emissions, biogenic | O10: 0 | P10: 0 | Q10: 0 | R10: USD per kg
A11: CAPEX contribution | B11: - | C11: - | D11: =O13 -> 0.064391686 | E11: =D11 -> 0.064391686 | F11: =E11 -> 0.064391686
A12: Fixed costs contribution | B12: - | C12: - | D12: =O14 -> 0.032994087 | E12: =D12 -> 0.032994087 | F12: =E12 -> 0.032994087 | N12: For fossil routes
N13: CAPEX contribution | O13: =0.056*596.2/607.5*596.2/550.8*596.2/550.8 -> 0.064391686 | P13: 0 | Q13: 0 | R13: USD2019 kg-1 methanol
A14: Blue methanol | D14: Cost | E14: Low | F14: High | N14: Fixed costs contribution | O14: =0.0286942148760331*596.2/607.5*596.2/550.8*596.2/550.8 -> 0.032994087 | P14: 0 | Q14: 0 | R14: USD2019 kg-1 methanol
A15: methanol | B15: 1 | C15: kilogram | D15: =SUM(D16:D25) -> 0.57895768 | E15: =SUM(E16:E25) -> 0.14756899 | F15: =SUM(F16:F25) -> 2.2539899
A16: natural gas, feedstock | B16: 0.65179 | C16: cubic meter | D16: =$B16*O3 -> 0.35532395 | E16: =$B16*P3 -> 0.035754723 | F16: =$B16*Q3 -> 1.5849116 | N16: For green routes
A17: natural gas, heating | B17: 6.93 | C17: cubic meter | D17: =$B17*O4 -> 0.10323052 | E17: =$B17*P4 -> 0.010387643 | F17: =$B17*Q4 -> 0.46045657 | N17: CAPEX contribution | O17: =0.092*596.2/607.5*596.2/550.8*596.2/550.8 -> 0.10578634 | P17: 0 | Q17: 0 | R17: USD2019 kg-1 methanol
A18: electricity, from grid | B18: 0.237 | C18: kilowatt hour | D18: =$B18*O5 -> 0.02301744 | E18: =$B18*P5 -> 0.00404085 | F18: =$B18*Q5 -> 0.11123595 | N18: Fixed costs contribution | O18: =0.0471404958677686*596.2/607.5*596.2/550.8*596.2/550.8 -> 0.054204572 | P18: 0 | Q18: 0 | R18: USD2019 kg-1 methanol
A19: solar hydrogen, 25 bar | B19: 0 | C19: kilogram | D19: =$B19*O6 -> 0 | E19: =$B19*P6 -> 0 | F19: =$B19*Q6 -> 0
A20: wind hydrogen, 25 bar | B20: 0 | C20: kilogram | D20: =$B20*O7 -> 0 | E20: =$B20*P7 -> 0 | F20: =$B20*Q7 -> 0
A21: carbon dioxide gaseous | B21: 0 | C21: kilogram | D21: =$B21*O8 -> 0 | E21: =$B21*P8 -> 0 | F21: =$B21*Q8 -> 0
A22: CO2 emissions, fossil | B22: 0 | C22: kilogram | D22: =$B22*O9 -> 0 | E22: =$B22*P9 -> 0 | F22: =$B22*Q9 -> 0
A23: CO2 emissions, biogenic | B23: 0 | C23: kilogram | D23: =$B23*O10 -> 0 | E23: =$B23*P10 -> 0 | F23: =$B23*Q10 -> 0
A24: CAPEX contribution | B24: - | C24: - | D24: =O13 -> 0.064391686 | E24: =D24 -> 0.064391686 | F24: =E24 -> 0.064391686
A25: Fixed costs contribution | B25: - | C25: - | D25: =O14 -> 0.032994087 | E25: =D25 -> 0.032994087 | F25: =E25 -> 0.032994087
A27: Solar methanol | D27: Cost | E27: Low | F27: High
A28: methanol | B28: 1 | C28: kilogram | D28: =SUM(D29:D38) -> 0.93643347 | E28: =SUM(E29:E38) -> 0.85659044 | F28: =SUM(F29:F38) -> 1.1047704
A29: natural gas, feedstock | B29: 0 | C29: cubic meter | D29: =$B29*O3 -> 0 | E29: =$B29*P3 -> 0 | F29: =$B29*Q3 -> 0
A30: natural gas, heating | B30: 0 | C30: megajoule | D30: =$B30*O4 -> 0 | E30: =$B30*P4 -> 0 | F30: =$B30*Q4 -> 0
A31: electricity, from grid | B31: 0.30289532 | C31: kilowatt hour | D31: =$B31*O5 -> 0.029417194 | E31: =$B31*P5 -> 0.0051643653 | F31: =$B31*Q5 -> 0.14216392
A32: solar hydrogen, 25 bar | B32: 0.1389755 | C32: kilogram | D32: =$B32*O6 -> 0.2501559 | E32: =$B32*P6 -> 0.1945657 | F32: =$B32*Q6 -> 0.3057461
A33: wind hydrogen, 25 bar | B33: 0 | C33: kilogram | D33: =$B33*O7 -> 0 | E33: =$B33*P7 -> 0 | F33: =$B33*Q7 -> 0
A34: carbon dioxide gaseous | B34: 1.6904232 | C34: kilogram | D34: =$B34*O8 -> 0.49686946 | E34: =$B34*P8 -> 0.49686946 | F34: =$B34*Q8 -> 0.49686946
A35: CO2 emissions, fossil | B35: 0 | C35: kilogram | D35: =$B35*O9 -> 0 | E35: =$B35*P9 -> 0 | F35: =$B35*Q9 -> 0
A36: CO2 emissions, biogenic | B36: 0 | C36: kilogram | D36: =$B36*O10 -> 0 | E36: =$B36*P10 -> 0 | F36: =$B36*Q10 -> 0
A37: CAPEX contribution | B37: - | C37: - | D37: =O17 -> 0.10578634 | E37: =D37 -> 0.10578634 | F37: =E37 -> 0.10578634
A38: Fixed costs contribution | B38: - | C38: - | D38: =O18 -> 0.054204572 | E38: =D38 -> 0.054204572 | F38: =E38 -> 0.054204572
A40: Wind methanol | D40: Cost | E40: Low | F40: High
A41: methanol | B41: 1 | C41: kilogram | D41: =SUM(D42:D51) -> 0.96422857 | E41: =SUM(E42:E51) -> 0.88438554 | F41: =SUM(F42:F51) -> 1.1603606
A42: natural gas, feedstock | B42: 0 | C42: cubic meter | D42: =$B42*O3 -> 0 | E42: =$B42*P3 -> 0 | F42: =$B42*Q3 -> 0
...

Sheet 2050
A1: Fossil methanol | D1: Cost | E1: Low | F1: High | N1: Prices
A2: methanol | B2: 1 | C2: kilogram | D2: =SUM(D3:D12) -> 0.5711542 | E2: =SUM(E3:E12) -> 0.15281692 | F2: =SUM(F3:F12) -> 2.185513 | N2: Category | O2: Price | P2: Low | Q2: High
A3: natural gas, feedstock | B3: 0.65179 | C3: cubic meter | D3: =$B3*O3 -> 0.35532395 | E3: =$B3*P3 -> 0.035754723 | F3: =$B3*Q3 -> 1.5849116 | N3: natural gas, feedstock | O3: =701.61/1000*0.777 -> 0.54515097 | P3: =70.6/1000*0.777 -> 0.0548562 | Q3: =3129.51/1000*0.777 -> 2.4316293 | R3: USD per m3
A4: natural gas, heating | B4: 6.93 | C4: megajoule | D4: =$B4*O4 -> 0.10323052 | E4: =$B4*P4 -> 0.010387643 | F4: =$B4*Q4 -> 0.46045657 | N4: natural gas, heating | O4: =701.61/1000/47.1 -> 0.014896178 | P4: =70.6/1000/47.1 -> 0.0014989384 | Q4: =3129.51/1000/47.1 -> 0.066443949 | R4: USD per MJ
A5: electricity, from grid | B5: 0.074 | C5: kilowatt hour | D5: =$B5*O5 -> 0.00718688 | E5: =$B5*P5 -> 0.0012617 | F5: =$B5*Q5 -> 0.0347319 | N5: electricity, from grid | O5: =97.12/1000 -> 0.09712 | P5: =17.05/1000 -> 0.01705 | Q5: =469.35/1000 -> 0.46935 | R5: USD per kWh
A6: solar hydrogen, 25 bar | B6: 0 | C6: kilogram | D6: =$B6*O6 -> 0 | E6: =$B6*P6 -> 0 | F6: =$B6*Q6 -> 0 | N6: solar hydrogen, 25 bar | O6: 1.5 | P6: 1 | Q6: 1.8 | R6: USD per kg
A7: wind hydrogen, 25 bar | B7: 0 | C7: kilogram | D7: =$B7*O7 -> 0 | E7: =$B7*P7 -> 0 | F7: =$B7*Q7 -> 0 | N7: wind hydrogen, 25 bar | O7: 1.8 | P7: 1.2 | Q7: 2.2 | R7: USD per kg
A8: carbon dioxide gaseous | B8: 0 | C8: kilogram | D8: =$B8*O8 -> 0 | E8: =$B8*P8 -> 0 | F8: =$B8*Q8 -> 0 | N8: carbon dioxide gaseous | O8: =214/1000 -> 0.214 | P8: =214/1000 -> 0.214 | Q8: =214/1000 -> 0.214 | R8: USD per kg
A9: CO2 emissions, fossil | B9: 0 | C9: kilogram | D9: =$B9*O9 -> 0 | E9: =$B9*P9 -> 0 | F9: =$B9*Q9 -> 0 | N9: CO2 emissions, fossil | O9: 0 | P9: 0 | Q9: 0 | R9: USD per kg
A10: CO2 emissions, biogenic | B10: 0 | C10: kilogram | D10: =$B10*O10 -> 0 | E10: =$B10*P10 -> 0 | F10: =$B10*Q10 -> 0 | N10: CO2 emissions, biogenic | O10: 0 | P10: 0 | Q10: 0 | R10: USD per kg
A11: CAPEX contribution | B11: - | C11: - | D11: =O13 -> 0.069699207 | E11: =D11 -> 0.069699207 | F11: =E11 -> 0.069699207
A12: Fixed costs contribution | B12: - | C12: - | D12: =O14 -> 0.035713643 | E12: =D12 -> 0.035713643 | F12: =E12 -> 0.035713643 | N12: For fossil routes
N13: CAPEX contribution | O13: =0.056*596.2/607.5*596.2/550.8*596.2/550.8*596.2/550.8 -> 0.069699207 | P13: 0 | Q13: 0 | R13: USD2019 kg-1 methanol
A14: Blue methanol | D14: Cost | E14: Low | F14: High | N14: Fixed costs contribution | O14: =0.0286942148760331*596.2/607.5*596.2/550.8*596.2/550.8*596.2/550.8 -> 0.035713643 | P14: 0 | Q14: 0 | R14: USD2019 kg-1 methanol
A15: methanol | B15: 1 | C15: kilogram | D15: =SUM(D16:D25) -> 0.58698476 | E15: =SUM(E16:E25) -> 0.15559607 | F15: =SUM(F16:F25) -> 2.262017
A16: natural gas, feedstock | B16: 0.65179 | C16: cubic meter | D16: =$B16*O3 -> 0.35532395 | E16: =$B16*P3 -> 0.035754723 | F16: =$B16*Q3 -> 1.5849116 | N16: For green routes
A17: natural gas, heating | B17: 6.93 | C17: cubic meter | D17: =$B17*O4 -> 0.10323052 | E17: =$B17*P4 -> 0.010387643 | F17: =$B17*Q4 -> 0.46045657 | N17: CAPEX contribution | O17: =0.092*596.2/607.5*596.2/550.8*596.2/550.8*596.2/550.8 -> 0.11450584 | P17: 0 | Q17: 0 | R17: USD2019 kg-1 methanol
A18: electricity, from grid | B18: 0.237 | C18: kilowatt hour | D18: =$B18*O5 -> 0.02301744 | E18: =$B18*P5 -> 0.00404085 | F18: =$B18*Q5 -> 0.11123595 | N18: Fixed costs contribution | O18: =0.0471404958677686*596.2/607.5*596.2/550.8*596.2/550.8*596.2/550.8 -> 0.058672414 | P18: 0 | Q18: 0 | R18: USD2019 kg-1 methanol
A19: solar hydrogen, 25 bar | B19: 0 | C19: kilogram | D19: =$B19*O6 -> 0 | E19: =$B19*P6 -> 0 | F19: =$B19*Q6 -> 0
A20: wind hydrogen, 25 bar | B20: 0 | C20: kilogram | D20: =$B20*O7 -> 0 | E20: =$B20*P7 -> 0 | F20: =$B20*Q7 -> 0
A21: carbon dioxide gaseous | B21: 0 | C21: kilogram | D21: =$B21*O8 -> 0 | E21: =$B21*P8 -> 0 | F21: =$B21*Q8 -> 0
A22: CO2 emissions, fossil | B22: 0 | C22: kilogram | D22: =$B22*O9 -> 0 | E22: =$B22*P9 -> 0 | F22: =$B22*Q9 -> 0
A23: CO2 emissions, biogenic | B23: 0 | C23: kilogram | D23: =$B23*O10 -> 0 | E23: =$B23*P10 -> 0 | F23: =$B23*Q10 -> 0
A24: CAPEX contribution | B24: - | C24: - | D24: =O13 -> 0.069699207 | E24: =D24 -> 0.069699207 | F24: =E24 -> 0.069699207
A25: Fixed costs contribution | B25: - | C25: - | D25: =O14 -> 0.035713643 | E25: =D25 -> 0.035713643 | F25: =E25 -> 0.035713643
A27: Solar methanol | D27: Cost | E27: Low | F27: High
A28: methanol | B28: 1 | C28: kilogram | D28: =SUM(D29:D38) -> 0.77280926 | E28: =SUM(E29:E38) -> 0.67906868 | F28: =SUM(F29:F38) -> 0.92724863
A29: natural gas, feedstock | B29: 0 | C29: cubic meter | D29: =$B29*O3 -> 0 | E29: =$B29*P3 -> 0 | F29: =$B29*Q3 -> 0
A30: natural gas, heating | B30: 0 | C30: megajoule | D30: =$B30*O4 -> 0 | E30: =$B30*P4 -> 0 | F30: =$B30*Q4 -> 0
A31: electricity, from grid | B31: 0.30289532 | C31: kilowatt hour | D31: =$B31*O5 -> 0.029417194 | E31: =$B31*P5 -> 0.0051643653 | F31: =$B31*Q5 -> 0.14216392
A32: solar hydrogen, 25 bar | B32: 0.1389755 | C32: kilogram | D32: =$B32*O6 -> 0.20846325 | E32: =$B32*P6 -> 0.1389755 | F32: =$B32*Q6 -> 0.2501559
A33: wind hydrogen, 25 bar | B33: 0 | C33: kilogram | D33: =$B33*O7 -> 0 | E33: =$B33*P7 -> 0 | F33: =$B33*Q7 -> 0
A34: carbon dioxide gaseous | B34: 1.6904232 | C34: kilogram | D34: =$B34*O8 -> 0.36175056 | E34: =$B34*P8 -> 0.36175056 | F34: =$B34*Q8 -> 0.36175056
A35: CO2 emissions, fossil | B35: 0 | C35: kilogram | D35: =$B35*O9 -> 0 | E35: =$B35*P9 -> 0 | F35: =$B35*Q9 -> 0
A36: CO2 emissions, biogenic | B36: 0 | C36: kilogram | D36: =$B36*O10 -> 0 | E36: =$B36*P10 -> 0 | F36: =$B36*Q10 -> 0
A37: CAPEX contribution | B37: - | C37: - | D37: =O17 -> 0.11450584 | E37: =D37 -> 0.11450584 | F37: =E37 -> 0.11450584
A38: Fixed costs contribution | B38: - | C38: - | D38: =O18 -> 0.058672414 | E38: =D38 -> 0.058672414 | F38: =E38 -> 0.058672414
A40: Wind methanol | D40: Cost | E40: Low | F40: High
A41: methanol | B41: 1 | C41: kilogram | D41: =SUM(D42:D51) -> 0.81450191 | E41: =SUM(E42:E51) -> 0.70686378 | F41: =SUM(F42:F51) -> 0.98283883
A42: natural gas, feedstock | B42: 0 | C42: cubic meter | D42: =$B42*O3 -> 0 | E42: =$B42*P3 -> 0 | F42: =$B42*Q3 -> 0
...

Sheet Overall
B1: Fossil 2020 | C1: Fossil 2030 | D1: Fossil 2040 | E1: Fossil 2050 | F1: Blue 2020 | G1: Blue 2030 | H1: Blue 2040 | I1: Blue 2050 | J1: Solar 2020 | K1: Solar 2030 | L1: Solar 2040 | M1: Solar 2050 | N1: Wind 2020 | O1: Wind 2030 | P1: Wind 2040 | Q1: Wind 2050
A2: natural gas, feedstock | B2: ='2020'!D3 -> 0.073373147 | C2: ='2030'!D3 -> 0.35532395 | D2: ='2040'!D3 -> 0.35532395 | E2: ='2050'!D3 -> 0.35532395 | F2: ='2020'!D16 -> 0.073373147 | G2: ='2030'!D16 -> 0.35532395 | H2: ='2040'!D16 -> 0.35532395 | I2: ='2050'!D16 -> 0.35532395 | J2: ='2020'!D29 -> 0 | K2: ='2030'!D29 -> 0 | L2: ='2040'!D29 -> 0 | M2: ='2050'!D29 -> 0 | N2: ='2020'!D42 -> 0 | O2: ='2030'!D42 -> 0 | P2: ='2040'!D42 -> 0 | Q2: ='2050'!D42 -> 0
A3: natural gas, heating | B3: ='2020'!D4 -> 0.021316739 | C3: ='2030'!D4 -> 0.10323052 | D3: ='2040'!D4 -> 0.10323052 | E3: ='2050'!D4 -> 0.10323052 | F3: ='2020'!D17 -> 0.021316739 | G3: ='2030'!D17 -> 0.10323052 | H3: ='2040'!D17 -> 0.10323052 | I3: ='2050'!D17 -> 0.10323052 | J3: ='2020'!D30 -> 0 | K3: ='2030'!D30 -> 0 | L3: ='2040'!D30 -> 0 | M3: ='2050'!D30 -> 0 | N3: ='2020'!D43 -> 0 | O3: ='2030'!D43 -> 0 | P3: ='2040'!D43 -> 0 | Q3: ='2050'!D43 -> 0
A4: electricity, from grid | B4: ='2020'!D5 -> 0.00225256 | C4: ='2030'!D5 -> 0.00718688 | D4: ='2040'!D5 -> 0.00718688 | E4: ='2050'!D5 -> 0.00718688 | F4: ='2020'!D18 -> 0.00721428 | G4: ='2030'!D18 -> 0.02301744 | H4: ='2040'!D18 -> 0.02301744 | I4: ='2050'!D18 -> 0.02301744 | J4: ='2020'!D31 -> 0.0092201336 | K4: ='2030'!D31 -> 0.029417194 | L4: ='2040'!D31 -> 0.029417194 | M4: ='2050'!D31 -> 0.029417194 | N4: ='2020'!D44 -> 0.0092201336 | O4: ='2030'!D44 -> 0.029417194 | P4: ='2040'!D44 -> 0.029417194 | Q4: ='2050'!D44 -> 0.029417194
A5: solar hydrogen, 25 bar | B5: ='2020'!D6 -> 0 | C5: ='2030'!D6 -> 0 | D5: ='2040'!D6 -> 0 | E5: ='2050'!D6 -> 0 | F5: ='2020'!D19 -> 0 | G5: ='2030'!D19 -> 0 | H5: ='2040'!D19 -> 0 | I5: ='2050'!D19 -> 0 | J5: ='2020'!D32 -> 0.4447216 | K5: ='2030'!D32 -> 0.34743875 | L5: ='2040'!D32 -> 0.2501559 | M5: ='2050'!D32 -> 0.20846325 | N5: ='2020'!D45 -> 0 | O5: ='2030'!D45 -> 0 | P5: ='2040'!D45 -> 0 | Q5: ='2050'!D45 -> 0
A6: wind hydrogen, 25 bar | B6: ='2020'!D7 -> 0 | C6: ='2030'!D7 -> 0 | D6: ='2040'!D7 -> 0 | E6: ='2050'!D7 -> 0 | F6: ='2020'!D20 -> 0 | G6: ='2030'!D20 -> 0 | H6: ='2040'!D20 -> 0 | I6: ='2050'!D20 -> 0 | J6: ='2020'!D33 -> 0 | K6: ='2030'!D33 -> 0 | L6: ='2040'!D33 -> 0 | M6: ='2050'!D33 -> 0 | N6: ='2020'!D46 -> 0.4169265 | O6: ='2030'!D46 -> 0.34743875 | P6: ='2040'!D46 -> 0.277951 | Q6: ='2050'!D46 -> 0.2501559
A7: carbon dioxide gaseous | B7: ='2020'!D8 -> 0 | C7: ='2030'!D8 -> 0 | D7: ='2040'!D8 -> 0 | E7: ='2050'!D8 -> 0 | F7: ='2020'!D21 -> 0 | G7: ='2030'!D21 -> 0 | H7: ='2040'!D21 -> 0 | I7: ='2050'!D21 -> 0 | J7: ='2020'!D34 -> 0.76576169 | K7: ='2030'!D34 -> 0.6315404 | L7: ='2040'!D34 -> 0.49686946 | M7: ='2050'!D34 -> 0.36175056 | N7: ='2020'!D47 -> 0.76576169 | O7: ='2030'!D47 -> 0.6315404 | P7: ='2040'!D47 -> 0.49686946 | Q7: ='2050'!D47 -> 0.36175056
A8: CO2 emissions, fossil | B8: ='2020'!D9 -> 0 | C8: ='2030'!D9 -> 0 | D8: ='2040'!D9 -> 0 | E8: ='2050'!D9 -> 0 | F8: ='2020'!D22 -> 0 | G8: ='2030'!D22 -> 0 | H8: ='2040'!D22 -> 0 | I8: ='2050'!D22 -> 0 | J8: ='2020'!D35 -> 0 | K8: ='2030'!D35 -> 0 | L8: ='2040'!D35 -> 0 | M8: ='2050'!D35 -> 0 | N8: ='2020'!D48 -> 0 | O8: ='2030'!D48 -> 0 | P8: ='2040'!D48 -> 0 | Q8: ='2050'!D48 -> 0
A9: CO2 emissions, biogenic | B9: ='2020'!D10 -> 0 | C9: ='2030'!D10 -> 0 | D9: ='2040'!D10 -> 0 | E9: ='2050'!D10 -> 0 | F9: ='2020'!D23 -> 0 | G9: ='2030'!D23 -> 0 | H9: ='2040'!D23 -> 0 | I9: ='2050'!D23 -> 0 | J9: ='2020'!D36 -> 0 | K9: ='2030'!D36 -> 0 | L9: ='2040'!D36 -> 0 | M9: ='2050'!D36 -> 0 | N9: ='2020'!D49 -> 0 | O9: ='2030'!D49 -> 0 | P9: ='2040'!D49 -> 0 | Q9: ='2050'!D49 -> 0
A10: CAPEX contribution | B10: ='2020'!D11 -> 0.054958354 | C10: ='2030'!D11 -> 0.059488327 | D10: ='2040'!D11 -> 0.064391686 | E10: ='2050'!D11 -> 0.069699207 | F10: ='2020'!D24 -> 0.054958354 | G10: ='2030'!D24 -> 0.059488327 | H10: ='2040'!D24 -> 0.064391686 | I10: ='2050'!D24 -> 0.069699207 | J10: ='2020'!D37 -> 0.090288724 | K10: ='2030'!D37 -> 0.097730823 | L10: ='2040'!D37 -> 0.10578634 | M10: ='2050'!D37 -> 0.11450584 | N10: ='2020'!D50 -> 0.090288724 | O10: ='2030'!D50 -> 0.097730823 | P10: ='2040'!D50 -> 0.10578634 | Q10: ='2050'!D50 -> 0.11450584
A11: Fixed costs contribution | B11: ='2020'!D12 -> 0.028160479 | C11: ='2030'!D12 -> 0.030481622 | D11: ='2040'!D12 -> 0.032994087 | E11: ='2050'!D12 -> 0.035713643 | F11: ='2020'!D25 -> 0.028160479 | G11: ='2030'!D25 -> 0.030481622 | H11: ='2040'!D25 -> 0.032994087 | I11: ='2050'!D25 -> 0.035713643 | J11: ='2020'!D38 -> 0.046263644 | K11: ='2030'!D38 -> 0.050076951 | L11: ='2040'!D38 -> 0.054204572 | M11: ='2050'!D38 -> 0.058672414 | N11: ='2020'!D51 -> 0.046263644 | O11: ='2030'!D51 -> 0.050076951 | P11: ='2040'!D51 -> 0.054204572 | Q11: ='2050'!D51 -> 0.058672414
A12: Low | B12: ='2020'!E2 -> 0.1305229 | C12: ='2030'!E2 -> 0.13737402 | D12: ='2040'!E2 -> 0.14478984 | E12: ='2050'!E2 -> 0.15281692 | F12: ='2020'!E15 -> 0.13330205 | G12: ='2030'!E15 -> 0.14015317 | H12: ='2040'!E15 -> 0.14756899 | I12: ='2050'!E15 -> 0.15559607 | J12: ='2020'!E28 -> 1.2827123 | K12: ='2030'!E28 -> 1.0346684 | L12: ='2040'!E28 -> 0.85659044 | M12: ='2050'!E28 -> 0.67906868 | N12: ='2020'!E41 -> 1.2132245 | O12: ='2030'!E41 -> 1.0346684 | P12: ='2040'!E41 -> 0.88438554 | Q12: ='2050'!E41 -> 0.70686378
A13: High | B13: ='2020'!F2 -> 0.25748312 | C13: ='2030'!F2 -> 2.1700701 | D13: ='2040'!F2 -> 2.1774859 | E13: ='2050'!F2 -> 2.185513 | F13: ='2020'!F15 -> 0.26460296 | G13: ='2030'!F15 -> 2.2465741 | H13: ='2040'!F15 -> 2.2539899 | I13: ='2050'!F15 -> 2.262017 | J13: ='2020'!F28 -> 1.4714465 | K13: ='2030'!F28 -> 1.2967459 | L13: ='2040'!F28 -> 1.1047704 | M13: ='2050'!F28 -> 0.92724863 | N13: ='2020'!F41 -> 1.4714465 | O13: ='2030'!F41 -> 1.3384386 | P13: ='2040'!F41 -> 1.1603606 | Q13: ='2050'!F41 -> 0.98283883
